Workbook

Sheet Читать сначала
A1: Эко-тиры: unit-экономика прогрессивных бонусов за утилизацию
A2: Окно бонусов: 2025-06-01 — 2026-07-31 (14 мес). Разложение: по тирам и по месяцам с 01.2026.
A4: СУТЬ МЕХАНИКИ
A5: Коэффициент начисления эко-бонусов за сдачу вторсырья растёт вместе с валовой выручкой покупателя: 4 тира. Модель считает полную экономику — доход (грязная маржа с приростом ВВ) минус расход (все бонусные затраты, включая доплату тем, кто не менял поведение).
A7: ЧТО ИЗМЕНИЛОСЬ В ЭТОЙ ВЕРСИИ
A8: 1. Расчёт переведён на unit-экономику: базовая единица — один пользователь за один месяц. Тиры и периоды получаются масштабированием юнита на число пользователей. 2. Убрана связка с АСР-сегментами ВВ. Тир определяется только границей валовой выручки за календарный месяц: Старт < 3 000 ₽, Росток 3 000–12 000 ₽, Дерево 12 000–35 000 ₽, Лес ≥ 35 000 ₽. 3. База расчёта — валовая выручка. Грязная маржа = ВВ × ставка грязной маржи (лист «Допущения»). 4. Разложение по каждому тиру и по каждому месяцу начиная с 01.2026 — доходы и расходы (лист «Тир_Период»). 5. Все окна — в календарных месяцах. Окон «90 дней» и «30 дней» в модели больше нет: квалификация в тир — за календарный месяц, эмиссия бонусов нормирована на 14 месяцев фактической выгрузки.
A10: ПОЧЕМУ СНЯТИЕ СВЯЗКИ С СЕГМЕНТАМИ СИЛЬНО МЕНЯЕТ ЦИФРЫ
A11: В предыдущей версии тир присваивался по сегменту: Амбассадор → Лес (×2,85), Средний → Дерево (×2,15). Но по собственной экономике сегментов из АСР-выгрузки средняя ВВ Амбассадора ≈ 10 330 ₽/мес (5,0 покупок × 2 066 ₽), то есть до порога Леса в 35 000 ₽ он не доходит — это уровень Ростка. Средний ≈ 1 212 ₽/мес — это Старт. Связка «сегмент → тир» завышала присвоенные множители, а вместе с ними и «слепую доплату». По границам выручки доплата получается в несколько раз меньше — см. лист «Тир_Период».
A13: ДАННЫЕ
A14: • Факт (серое): выгрузка эко-бонусов 2025-06-01 — 2026-07-31: 248 950 карт 55 937 469 ₽ начислено за 14 мес = 3 995 533 ₽/мес = 16.05 ₽/юзер/мес. • Границы тиров и множители — из постановки задачи (жёлтое лист «Допущения»). • Ставка грязной маржи — допущение требует подтверждения финансами.
A16: ЧЕГО ПОКА НЕТ — И ЧТО ЭТО ЗНАЧИТ
A17: Выгрузка фактической валовой выручки по пользователям с начала 2026 года запрошена у аналитиков, но ещё не пришла. Поэтому распределение пользователей по тирам и средняя ВВ внутри тира на листе «Выручка_вход» — ПЛЕЙСХОЛДЕР (помечен жёлтым), а не факт. Он засеян логнормальным распределением со средней ВВ, собранной из агрегатов АСР-выгрузки, и log-СКО = 1.2 — только чтобы модель считалась от начала до конца и её можно было проверить. Когда выгрузка придёт, весь лист «Выручка_вход» пересобирается одной командой: python3 scripts/build_model.py --bonus-aggregates data/bonus_aggregates.json --revenue <файл.xlsx> Ни одна формула ниже при этом не меняется — меняются только входные числа.
... A26: Серое — факт, не менять. Жёлтое — допущения и ячейки под заполнение, их можно крутить. Синий шрифт — введённое руками число. Чёрный — формула. Зелёный — ссылка на другой лист.

Sheet Допущения
A1: Допущения и границы тиров
A2: Жёлтое — можно менять. Границы — в валовой выручке за КАЛЕНДАРНЫЙ МЕСЯЦ.
A4: A. Тиры: граница валовой выручки за календарный месяц
A5: Тир | B5: ВВ/мес от, ₽ | C5: ВВ/мес до, ₽ | D5: Множитель бонуса
A6: 🌱 Старт | B6: 0 | C6: 3000 | D6: 1 | F6: Тир присваивается по валовой выручке за месяц. Привязки к АСР-сегментам ВВ в расчёте нет.
A7: 🌿 Росток | B7: 3000 | C7: 12000 | D7: 1.4
A8: 🌳 Дерево | B8: 12000 | C8: 35000 | D8: 2.15
A9: 🌲 Лес | B9: 35000 | C9: без ограничения | D9: 2.85
A12: B. Экономика
A13: Параметр | B13: Значение | C13: Ед. | D13: Источник / комментарий
A14: Ставка грязной маржи | B14: 0.3 | C14: % от ВВ | D14: ДОПУЩЕНИЕ. Из полей «Маржа ВВ/мес» прошлой версии ставку вывести нельзя: для Репертуарного это 239%, для Среднего 149% от их же ВВ.
A15: Базовый эко-бонус | B15: 16.049542 | C15: ₽/юзер/мес | D15: ФАКТ: 55 937 469 ₽ / 248 950 карт / 14 мес. Источник: cec572a0-_________31_07_1_1.xlsx.
A16: Окно квалификации в тир | B16: 1 | C16: мес | D16: Заменяет прежнее условие «за 30 дн покупок». Все окна модели — в месяцах.
A17: Окно выгрузки бонусов | B17: =(YEAR(B19)-YEAR(B18))*12+MONTH(B19)-MONTH(B18)+1 -> 14 | C17: мес | D17: Число месяцев — формула от дат окна (B18, B19), а не константа. Заменяет прежнюю нормировку «×365/90».
A18: Начало окна выгрузки | B18: 45809 | C18: дата | D18: ФАКТ из выгрузки бонусов.
A19: Конец окна выгрузки | B19: 46234 | C19: дата | D19: ФАКТ из выгрузки бонусов.
A20: Последний закрытый месяц факта 2026 | B20: 7 | C20: номер мес | D20: Месяцы 2026 года до этого включительно попадают в окно выгрузки бонусов, дальше — прогноз.
A22: C. Индекс базового эко-бонуса по тирам
A23: Во сколько раз начисление на юзера в тире отличается от среднего. По умолчанию 1,00 — начисление не зависит от тира.
A24: Тир | B24: Индекс | C24: Базовый бонус, ₽/юзер/мес | D24: Основание
A25: 🌱 Старт | B25: 1 | C25: =$B$15*B25 -> 16.049542 | D25: ФАКТ-основание: по АСР-сегментам начисление на юзера почти не зависит от покупательной силы — индекс 0,68–1,21 без монотонного тренда (лист «Данные_бонусы»). Точную разбивку даст выгрузка бонусов в разрезе тиров.
A26: 🌿 Росток | B26: 1 | C26: =$B$15*B26 -> 16.049542
A27: 🌳 Дерево | B27: 1 | C27: =$B$15*B27 -> 16.049542
A28: 🌲 Лес | B28: 1 | C28: =$B$15*B28 -> 16.049542
A31: D. Индекс месяца для эмиссии бонусов
A32: 1,00 = эмиссия равна среднему за окно выгрузки. Правится, когда придёт разбивка начислений по месяцам.
A33: Месяц | B33: 2026-01 | C33: 2026-02 | D33: 2026-03 | E33: 2026-04 | F33: 2026-05 | G33: 2026-06 | H33: 2026-07 | I33: 2026-08 | J33: 2026-09 | K33: 2026-10 | L33: 2026-11 | M33: 2026-12
A34: Индекс | B34: 1 | C34: 1 | D34: 1 | E34: 1 | F34: 1 | G34: 1 | H34: 1 | I34: 1 | J34: 1 | K34: 1 | L34: 1 | M34: 1

Sheet Данные_бонусы
A1: Факт: выгрузка эко-бонусов
A2: cec572a0-_________31_07_1_1.xlsx · 2025-06-01 — 2026-07-31 · серое = факт, не менять
A4: A. Итог по выгрузке
A5: Показатель | B5: Значение | C5: Ед. | D5: Как получено
A6: Карт участников | B6: 248950 | C6: шт | D6: Строк в выгрузке (дублей карт нет)
A7: Начислено за окно | B7: 55937469 | C7: ₽ | D7: Сумма bonusvalue
A8: Месяцев в окне | B8: =Допущения!B17 -> 14 | C8: мес | D8: Ссылка на «Допущения»
A9: Эмиссия в месяц | B9: =B7/B8 -> 3995533.5 | C9: ₽/мес | D9: Ссылка на «Допущения»
A10: Эмиссия в год | B10: =B9*12 -> 47946402 | C10: ₽/год | D10: Ссылка на «Допущения»
A11: Базовый бонус на юзера | B11: =B9/B6 -> 16.049542 | C11: ₽/юзер/мес | D11: Ссылка на «Допущения»
A14: B. Распределение начислений на карту за всё окно
A15: Распределение крайне скошенное: медиана 50 ₽ за 14 мес против средних 224,69 ₽ — четверть карт получила меньше 20 ₽. Это про расходную часть: множитель к почти нулевой базе почти ничего не стоит.
A16: Квантиль | B16: ₽ за окно | C16: ₽/юзер/мес
A17: минимум | B17: 0.05 | C17: =B17/Допущения!$B$17 -> 0.0035714286
A18: 10-й перцентиль | B18: 7 | C18: =B18/Допущения!$B$17 -> 0.5
A19: 25-й перцентиль | B19: 19.95 | C19: =B19/Допущения!$B$17 -> 1.425
A20: медиана | B20: 50 | C20: =B20/Допущения!$B$17 -> 3.5714286
A21: 75-й перцентиль | B21: 161.25 | C21: =B21/Допущения!$B$17 -> 11.517857
A22: 90-й перцентиль | B22: 457.1 | C22: =B22/Допущения!$B$17 -> 32.65
A23: 95-й перцентиль | B23: 854.955 | C23: =B23/Допущения!$B$17 -> 61.068214
A24: 99-й перцентиль | B24: 2793.057 | C24: =B24/Допущения!$B$17 -> 199.50407
A25: максимум | B25: 114072.4 | C25: =B25/Допущения!$B$17 -> 8148.0286
A28: C. Справочно: АСР-сегменты ВВ — В РАСЧЁТЕ НЕ УЧАСТВУЮТ
A29: Оставлено как доказательство одного факта: начисление эко-бонусов на юзера почти не зависит от покупательной силы. У Амбассадора оно НИЖЕ, чем у Репертуарного. Поэтому индекс базового бонуса по тирам взят 1,00.
A30: Сегмент АСР | B30: Карт | C30: Начислено за окно, ₽ | D30: ₽/юзер/мес | E30: Индекс к среднему
A31: Средний | B31: 84909 | C31: 21517830 | D31: =C31/B31/Допущения!$B$17 -> 18.10159 | E31: =IFERROR(D31/$D$35,0) -> 1.1278571
A32: Репертуарный | B32: 70459 | C32: 19204675 | D32: =C32/B32/Допущения!$B$17 -> 19.468947 | E32: =IFERROR(D32/$D$35,0) -> 1.2130531
A33: Амбассадор | B33: 51329 | C33: 8765901 | D33: =C33/B33/Допущения!$B$17 -> 12.19848 | E33: =IFERROR(D33/$D$35,0) -> 0.76005161
A34: (нет сегмента) | B34: 42253 | C34: 6449062.4 | D34: =C34/B34/Допущения!$B$17 -> 10.902121 | E34: =IFERROR(D34/$D$35,0) -> 0.67927925
A35: ИТОГО | B35: =SUM(B31:B34) -> 248950 | C35: =SUM(C31:C34) -> 55937469 | D35: =C35/B35/Допущения!$B$17 -> 16.049542 | E35: =IFERROR(D35/$D$35,0) -> 1

Sheet Выручка_вход
A1: Вход: валовая выручка по тирам и месяцам 2026 года
A2: ПЛЕЙСХОЛДЕР — заменить фактической выгрузкой ВВ по пользователям
A3: ВНИМАНИЕ: числа ниже — НЕ ФАКТ. Выгрузка фактической ВВ по пользователям с начала 2026 года запрошена у аналитиков и ещё не получена. Плейсхолдер засеян логнормальным распределением (средняя ВВ 2 614 ₽/мес из агрегатов АСР log-СКО 1.2) только чтобы модель считалась и её можно было проверить. Пересборка при получении файла: scripts/build_model.py --revenue <файл.xlsx>
A5: Месяц | B5: Статус | C5: Юзеров: 🌱 Старт | D5: Юзеров: 🌿 Росток | E5: Юзеров: 🌳 Дерево | F5: Юзеров: 🌲 Лес | G5: ВВ/юзер/мес: 🌱 Старт | H5: ВВ/юзер/мес: 🌿 Росток | I5: ВВ/юзер/мес: 🌳 Дерево | J5: ВВ/юзер/мес: 🌲 Лес | K5: Всего юзеров | L5: ВВ когорты, ₽/мес
A6: 2026-01 | B6: =IF(1<=Допущения!$B$20,"в окне выгрузки","прогноз") -> в окне выгрузки | C6: 189856 | D6: 51441 | E6: 6938 | F6: 715 | G6: 1075 | H6: 5501 | I6: 18036 | J6: 53826 | K6: =SUM(C6:F6) -> 248950 | L6: =SUMPRODUCT(C6:F6,G6:J6) -> 650691499
A7: 2026-02 | B7: =IF(2<=Допущения!$B$20,"в окне выгрузки","прогноз") -> в окне выгрузки | C7: 189856 | D7: 51441 | E7: 6938 | F7: 715 | G7: 1075 | H7: 5501 | I7: 18036 | J7: 53826 | K7: =SUM(C7:F7) -> 248950 | L7: =SUMPRODUCT(C7:F7,G7:J7) -> 650691499
A8: 2026-03 | B8: =IF(3<=Допущения!$B$20,"в окне выгрузки","прогноз") -> в окне выгрузки | C8: 189856 | D8: 51441 | E8: 6938 | F8: 715 | G8: 1075 | H8: 5501 | I8: 18036 | J8: 53826 | K8: =SUM(C8:F8) -> 248950 | L8: =SUMPRODUCT(C8:F8,G8:J8) -> 650691499
A9: 2026-04 | B9: =IF(4<=Допущения!$B$20,"в окне выгрузки","прогноз") -> в окне выгрузки | C9: 189856 | D9: 51441 | E9: 6938 | F9: 715 | G9: 1075 | H9: 5501 | I9: 18036 | J9: 53826 | K9: =SUM(C9:F9) -> 248950 | L9: =SUMPRODUCT(C9:F9,G9:J9) -> 650691499
A10: 2026-05 | B10: =IF(5<=Допущения!$B$20,"в окне выгрузки","прогноз") -> в окне выгрузки | C10: 189856 | D10: 51441 | E10: 6938 | F10: 715 | G10: 1075 | H10: 5501 | I10: 18036 | J10: 53826 | K10: =SUM(C10:F10) -> 248950 | L10: =SUMPRODUCT(C10:F10,G10:J10) -> 650691499
A11: 2026-06 | B11: =IF(6<=Допущения!$B$20,"в окне выгрузки","прогноз") -> в окне выгрузки | C11: 189856 | D11: 51441 | E11: 6938 | F11: 715 | G11: 1075 | H11: 5501 | I11: 18036 | J11: 53826 | K11: =SUM(C11:F11) -> 248950 | L11: =SUMPRODUCT(C11:F11,G11:J11) -> 650691499
A12: 2026-07 | B12: =IF(7<=Допущения!$B$20,"в окне выгрузки","прогноз") -> в окне выгрузки | C12: 189856 | D12: 51441 | E12: 6938 | F12: 715 | G12: 1075 | H12: 5501 | I12: 18036 | J12: 53826 | K12: =SUM(C12:F12) -> 248950 | L12: =SUMPRODUCT(C12:F12,G12:J12) -> 650691499
A13: 2026-08 | B13: =IF(8<=Допущения!$B$20,"в окне выгрузки","прогноз") -> прогноз | C13: 189856 | D13: 51441 | E13: 6938 | F13: 715 | G13: 1075 | H13: 5501 | I13: 18036 | J13: 53826 | K13: =SUM(C13:F13) -> 248950 | L13: =SUMPRODUCT(C13:F13,G13:J13) -> 650691499
A14: 2026-09 | B14: =IF(9<=Допущения!$B$20,"в окне выгрузки","прогноз") -> прогноз | C14: 189856 | D14: 51441 | E14: 6938 | F14: 715 | G14: 1075 | H14: 5501 | I14: 18036 | J14: 53826 | K14: =SUM(C14:F14) -> 248950 | L14: =SUMPRODUCT(C14:F14,G14:J14) -> 650691499
A15: 2026-10 | B15: =IF(10<=Допущения!$B$20,"в окне выгрузки","прогноз") -> прогноз | C15: 189856 | D15: 51441 | E15: 6938 | F15: 715 | G15: 1075 | H15: 5501 | I15: 18036 | J15: 53826 | K15: =SUM(C15:F15) -> 248950 | L15: =SUMPRODUCT(C15:F15,G15:J15) -> 650691499
A16: 2026-11 | B16: =IF(11<=Допущения!$B$20,"в окне выгрузки","прогноз") -> прогноз | C16: 189856 | D16: 51441 | E16: 6938 | F16: 715 | G16: 1075 | H16: 5501 | I16: 18036 | J16: 53826 | K16: =SUM(C16:F16) -> 248950 | L16: =SUMPRODUCT(C16:F16,G16:J16) -> 650691499
A17: 2026-12 | B17: =IF(12<=Допущения!$B$20,"в окне выгрузки","прогноз") -> прогноз | C17: 189856 | D17: 51441 | E17: 6938 | F17: 715 | G17: 1075 | H17: 5501 | I17: 18036 | J17: 53826 | K17: =SUM(C17:F17) -> 248950 | L17: =SUMPRODUCT(C17:F17,G17:J17) -> 650691499
A18: ИТОГО | B18: за 2026 год | C18: =AVERAGE(C6:C17) -> 189856 | D18: =AVERAGE(D6:D17) -> 51441 | E18: =AVERAGE(E6:E17) -> 6938 | F18: =AVERAGE(F6:F17) -> 715 | G18: =IFERROR(SUMPRODUCT(C6:C17,G6:G17)/SUM(C6:C17),0) -> 1075 | H18: =IFERROR(SUMPRODUCT(D6:D17,H6:H17)/SUM(D6:D17),0) -> 5501 | I18: =IFERROR(SUMPRODUCT(E6:E17,I6:I17)/SUM(E6:E17),0) -> 18036 | J18: =IFERROR(SUMPRODUCT(F6:F17,J6:J17)/SUM(F6:F17),0) -> 53826 | K18: =AVERAGE(K6:K17) -> 248950 | L18: =SUM(L6:L17) -> 7808297988
A20: Легенда: жёлтые ячейки C6:J17 — единственное, что нужно править вручную (или пересобрать скриптом). Всё остальное в книге — формулы от них.

Sheet Unit-экономика
A1: Unit-экономика: один пользователь за один месяц
A2: Базовая единица модели. Тиры и периоды на листе «Тир_Период» — это юнит × число юзеров.
A4: Показатель | B4: Ед. | C4: 🌱 Старт | D4: 🌿 Росток | E4: 🌳 Дерево | F4: 🌲 Лес | G4: Средневзв. по когорте
A5: Множитель бонуса тира | B5: × | C5: =Допущения!$D$6 -> 1 | D5: =Допущения!$D$7 -> 1.4 | E5: =Допущения!$D$8 -> 2.15 | F5: =Допущения!$D$9 -> 2.85 | G5: =IFERROR(SUMPRODUCT(C6:F6,C5:F5)/G6,0) -> 1.1200155
A6: Юзеров в тире (среднее за месяц 2026) | B6: чел | C6: =Выручка_вход!C$18 -> 189856 | D6: =Выручка_вход!D$18 -> 51441 | E6: =Выручка_вход!E$18 -> 6938 | F6: =Выручка_вход!F$18 -> 715 | G6: =SUM(C6:F6) -> 248950
A7: ДОХОД: валовая выручка | B7: ₽/юзер/мес | C7: =Выручка_вход!G$18 -> 1075 | D7: =Выручка_вход!H$18 -> 5501 | E7: =Выручка_вход!I$18 -> 18036 | F7: =Выручка_вход!J$18 -> 53826 | G7: =IFERROR(SUMPRODUCT(C7:F7,C6:F6)/G6,0) -> 2613.7437
A8: ДОХОД: грязная маржа | B8: ₽/юзер/мес | C8: =C7*Допущения!$B$14 -> 322.5 | D8: =D7*Допущения!$B$14 -> 1650.3 | E8: =E7*Допущения!$B$14 -> 5410.8 | F8: =F7*Допущения!$B$14 -> 16147.8 | G8: =IFERROR(SUMPRODUCT(C8:F8,C6:F6)/G6,0) -> 784.12312
A9: РАСХОД: эко-бонус базовый (без механики) | B9: ₽/юзер/мес | C9: =Допущения!$C$25 -> 16.049542 | D9: =Допущения!$C$26 -> 16.049542 | E9: =Допущения!$C$27 -> 16.049542 | F9: =Допущения!$C$28 -> 16.049542 | G9: =IFERROR(SUMPRODUCT(C9:F9,C6:F6)/G6,0) -> 16.049542
A10: РАСХОД: эко-бонус с механикой | B10: ₽/юзер/мес | C10: =C9*C5 -> 16.049542 | D10: =D9*D5 -> 22.469359 | E10: =E9*E5 -> 34.506515 | F10: =F9*F5 -> 45.741195 | G10: =IFERROR(SUMPRODUCT(C10:F10,C6:F6)/G6,0) -> 17.975735
A11: РАСХОД: доплата от механики (Δ бонус) | B11: ₽/юзер/мес | C11: =C10-C9 -> 0 | D11: =D10-D9 -> 6.4198168 | E11: =E10-E9 -> 18.456973 | F11: =F10-F9 -> 29.691653 | G11: =IFERROR(SUMPRODUCT(C11:F11,C6:F6)/G6,0) -> 1.9261932
A12: ВКЛАД: грязная маржа − бонус с механикой | B12: ₽/юзер/мес | C12: =C8-C10 -> 306.45046 | D12: =D8-D10 -> 1627.8306 | E12: =E8-E10 -> 5376.2935 | F12: =F8-F10 -> 16102.059 | G12: =IFERROR(SUMPRODUCT(C12:F12,C6:F6)/G6,0) -> 766.14738
A13: Бонус с механикой, % от грязной маржи | B13: % | C13: =IFERROR(C10/C8,0) -> 0.049766022 | D13: =IFERROR(D10/D8,0) -> 0.013615318 | E13: =IFERROR(E10/E8,0) -> 0.0063773407 | F13: =IFERROR(F10/F8,0) -> 0.002832658 | G13: =IFERROR(G10/G8,0) -> 0.022924634
A14: Доплата, % от грязной маржи | B14: % | C14: =IFERROR(C11/C8,0) -> 0 | D14: =IFERROR(D11/D8,0) -> 0.0038900908 | E14: =IFERROR(E11/E8,0) -> 0.0034111357 | F14: =IFERROR(F11/F8,0) -> 0.0018387429 | G14: =IFERROR(G11/G8,0) -> 0.0024564934
A15: Доплата, % от валовой выручки | B15: % | C15: =IFERROR(C11/C7,0) -> 0 | D15: =IFERROR(D11/D7,0) -> 0.0011670272 | E15: =IFERROR(E11/E7,0) -> 0.0010233407 | F15: =IFERROR(F11/F7,0) -> 0.00055162287 | G15: =IFERROR(G11/G7,0) -> 0.00073694802
A17: Как читать
A18: Строка «ВКЛАД» — сколько один пользователь тира приносит за месяц после всех бонусных затрат. Строка «Доплата, % от грязной маржи» — цена механики для этого тира: во что обходится повышенный коэффициент, если пользователь НЕ изменил поведение. Именно эта доплата, умноженная на число юзеров, даёт «слепые» затраты на листе «Тир_Период».

Sheet Тир_Период
A1: Разложение по тирам и месяцам 2026 года: доходы и расходы
A2: Один блок на тир, снизу — ИТОГО по когорте. Столбцы — месяцы, N — итог за 2026 год.
A4: Тир 🌱 Старт — ВВ/мес 0–3 000 ₽
A5: Показатель | B5: 2026-01 | C5: 2026-02 | D5: 2026-03 | E5: 2026-04 | F5: 2026-05 | G5: 2026-06 | H5: 2026-07 | I5: 2026-08 | J5: 2026-09 | K5: 2026-10 | L5: 2026-11 | M5: 2026-12 | N5: 2026 итого
A6: Юзеров в тире | B6: =Выручка_вход!C6 -> 189856 | C6: =Выручка_вход!C7 -> 189856 | D6: =Выручка_вход!C8 -> 189856 | E6: =Выручка_вход!C9 -> 189856 | F6: =Выручка_вход!C10 -> 189856 | G6: =Выручка_вход!C11 -> 189856 | H6: =Выручка_вход!C12 -> 189856 | I6: =Выручка_вход!C13 -> 189856 | J6: =Выручка_вход!C14 -> 189856 | K6: =Выручка_вход!C15 -> 189856 | L6: =Выручка_вход!C16 -> 189856 | M6: =Выручка_вход!C17 -> 189856 | N6: =AVERAGE(B6:M6) -> 189856
A7: Индекс месяца (эмиссия) | B7: =Допущения!B$34 -> 1 | C7: =Допущения!C$34 -> 1 | D7: =Допущения!D$34 -> 1 | E7: =Допущения!E$34 -> 1 | F7: =Допущения!F$34 -> 1 | G7: =Допущения!G$34 -> 1 | H7: =Допущения!H$34 -> 1 | I7: =Допущения!I$34 -> 1 | ... M7: =Допущения!M$34 -> 1 | N7: =AVERAGE(B7:M7) -> 1
A8: ДОХОД: валовая выручка, ₽ | B8: =B6*Выручка_вход!G6 -> 204095200 | C8: =C6*Выручка_вход!G7 -> 204095200 | D8: =D6*Выручка_вход!G8 -> 204095200 | E8: =E6*Выручка_вход!G9 -> 204095200 | F8: =F6*Выручка_вход!G10 -> 204095200 | G8: =G6*Выручка_вход!G11 -> 204095200 | H8: =H6*Выручка_вход!G12 -> 204095200 | I8: =I6*Выручка_вход!G13 -> 204095200 | J8: =J6*Выручка_вход!G14 -> 204095200 | K8: =K6*Выручка_вход!G15 -> 204095200 | L8: =L6*Выручка_вход!G16 -> 204095200 | M8: =M6*Выручка_вход!G17 -> 204095200 | N8: =SUM(B8:M8) -> 2449142400
A9: ДОХОД: грязная маржа, ₽ | B9: =B8*Допущения!$B$14 -> 61228560 | C9: =C8*Допущения!$B$14 -> 61228560 | D9: =D8*Допущения!$B$14 -> 61228560 | E9: =E8*Допущения!$B$14 -> 61228560 | F9: =F8*Допущения!$B$14 -> 61228560 | G9: =G8*Допущения!$B$14 -> 61228560 | H9: =H8*Допущения!$B$14 -> 61228560 | I9: =I8*Допущения!$B$14 -> 61228560 | ... M9: =M8*Допущения!$B$14 -> 61228560 | N9: =SUM(B9:M9) -> 734742720
A10: РАСХОД: эко-бонус базовый, ₽ | B10: =B6*Допущения!$C$25*B7 -> 3047101.8 | C10: =C6*Допущения!$C$25*C7 -> 3047101.8 | D10: =D6*Допущения!$C$25*D7 -> 3047101.8 | E10: =E6*Допущения!$C$25*E7 -> 3047101.8 | F10: =F6*Допущения!$C$25*F7 -> 3047101.8 | G10: =G6*Допущения!$C$25*G7 -> 3047101.8 | H10: =H6*Допущения!$C$25*H7 -> 3047101.8 | I10: =I6*Допущения!$C$25*I7 -> 3047101.8 | ... M10: =M6*Допущения!$C$25*M7 -> 3047101.8 | N10: =SUM(B10:M10) -> 36565222
A11: РАСХОД: эко-бонус с механикой, ₽ | B11: =B10*Допущения!$D$6 -> 3047101.8 | C11: =C10*Допущения!$D$6 -> 3047101.8 | D11: =D10*Допущения!$D$6 -> 3047101.8 | E11: =E10*Допущения!$D$6 -> 3047101.8 | F11: =F10*Допущения!$D$6 -> 3047101.8 | G11: =G10*Допущения!$D$6 -> 3047101.8 | H11: =H10*Допущения!$D$6 -> 3047101.8 | I11: =I10*Допущения!$D$6 -> 3047101.8 | ... M11: =M10*Допущения!$D$6 -> 3047101.8 | N11: =SUM(B11:M11) -> 36565222
A12: РАСХОД: доплата от механики, ₽ | B12: =B11-B10 -> 0 | C12: =C11-C10 -> 0 | D12: =D11-D10 -> 0 | E12: =E11-E10 -> 0 | F12: =F11-F10 -> 0 | G12: =G11-G10 -> 0 | H12: =H11-H10 -> 0 | I12: =I11-I10 -> 0 | ... M12: =M11-M10 -> 0 | N12: =SUM(B12:M12) -> 0
A13: ВКЛАД: маржа − бонус с механикой, ₽ | B13: =B9-B11 -> 58181458 | C13: =C9-C11 -> 58181458 | D13: =D9-D11 -> 58181458 | E13: =E9-E11 -> 58181458 | F13: =F9-F11 -> 58181458 | G13: =G9-G11 -> 58181458 | H13: =H9-H11 -> 58181458 | I13: =I9-I11 -> 58181458 | ... M13: =M9-M11 -> 58181458 | N13: =SUM(B13:M13) -> 6.981775e+08
A14: Доплата, % от грязной маржи | B14: =IFERROR(B12/B9,0) -> 0 | C14: =IFERROR(C12/C9,0) -> 0 | D14: =IFERROR(D12/D9,0) -> 0 | E14: =IFERROR(E12/E9,0) -> 0 | F14: =IFERROR(F12/F9,0) -> 0 | G14: =IFERROR(G12/G9,0) -> 0 | H14: =IFERROR(H12/H9,0) -> 0 | I14: =IFERROR(I12/I9,0) -> 0 | ... N14: =IFERROR(N12/N9,0) -> 0
A16: Тир 🌿 Росток — ВВ/мес 3 000–12 000 ₽
A17: Показатель | B17: 2026-01 | C17: 2026-02 | D17: 2026-03 | E17: 2026-04 | F17: 2026-05 | G17: 2026-06 | H17: 2026-07 | I17: 2026-08 | J17: 2026-09 | K17: 2026-10 | L17: 2026-11 | M17: 2026-12 | N17: 2026 итого
A18: Юзеров в тире | B18: =Выручка_вход!D6 -> 51441 | C18: =Выручка_вход!D7 -> 51441 | D18: =Выручка_вход!D8 -> 51441 | E18: =Выручка_вход!D9 -> 51441 | F18: =Выручка_вход!D10 -> 51441 | G18: =Выручка_вход!D11 -> 51441 | H18: =Выручка_вход!D12 -> 51441 | I18: =Выручка_вход!D13 -> 51441 | J18: =Выручка_вход!D14 -> 51441 | K18: =Выручка_вход!D15 -> 51441 | L18: =Выручка_вход!D16 -> 51441 | M18: =Выручка_вход!D17 -> 51441 | N18: =AVERAGE(B18:M18) -> 51441
A19: Индекс месяца (эмиссия) | B19: =Допущения!B$34 -> 1 | C19: =Допущения!C$34 -> 1 | D19: =Допущения!D$34 -> 1 | E19: =Допущения!E$34 -> 1 | F19: =Допущения!F$34 -> 1 | G19: =Допущения!G$34 -> 1 | H19: =Допущения!H$34 -> 1 | I19: =Допущения!I$34 -> 1 | ... M19: =Допущения!M$34 -> 1 | N19: =AVERAGE(B19:M19) -> 1
A20: ДОХОД: валовая выручка, ₽ | B20: =B18*Выручка_вход!H6 -> 282976941 | C20: =C18*Выручка_вход!H7 -> 282976941 | D20: =D18*Выручка_вход!H8 -> 282976941 | E20: =E18*Выручка_вход!H9 -> 282976941 | F20: =F18*Выручка_вход!H10 -> 282976941 | G20: =G18*Выручка_вход!H11 -> 282976941 | H20: =H18*Выручка_вход!H12 -> 282976941 | I20: =I18*Выручка_вход!H13 -> 282976941 | J20: =J18*Выручка_вход!H14 -> 282976941 | K20: =K18*Выручка_вход!H15 -> 282976941 | L20: =L18*Выручка_вход!H16 -> 282976941 | M20: =M18*Выручка_вход!H17 -> 282976941 | N20: =SUM(B20:M20) -> 3395723292
A21: ДОХОД: грязная маржа, ₽ | B21: =B20*Допущения!$B$14 -> 84893082 | C21: =C20*Допущения!$B$14 -> 84893082 | D21: =D20*Допущения!$B$14 -> 84893082 | E21: =E20*Допущения!$B$14 -> 84893082 | F21: =F20*Допущения!$B$14 -> 84893082 | G21: =G20*Допущения!$B$14 -> 84893082 | H21: =H20*Допущения!$B$14 -> 84893082 | I21: =I20*Допущения!$B$14 -> 84893082 | ... M21: =M20*Допущения!$B$14 -> 84893082 | N21: =SUM(B21:M21) -> 1.018717e+09
A22: РАСХОД: эко-бонус базовый, ₽ | B22: =B18*Допущения!$C$26*B19 -> 825604.49 | C22: =C18*Допущения!$C$26*C19 -> 825604.49 | D22: =D18*Допущения!$C$26*D19 -> 825604.49 | E22: =E18*Допущения!$C$26*E19 -> 825604.49 | F22: =F18*Допущения!$C$26*F19 -> 825604.49 | G22: =G18*Допущения!$C$26*G19 -> 825604.49 | H22: =H18*Допущения!$C$26*H19 -> 825604.49 | I22: =I18*Допущения!$C$26*I19 -> 825604.49 | ... M22: =M18*Допущения!$C$26*M19 -> 825604.49 | N22: =SUM(B22:M22) -> 9907253.9
A23: РАСХОД: эко-бонус с механикой, ₽ | B23: =B22*Допущения!$D$7 -> 1155846.3 | C23: =C22*Допущения!$D$7 -> 1155846.3 | D23: =D22*Допущения!$D$7 -> 1155846.3 | E23: =E22*Допущения!$D$7 -> 1155846.3 | F23: =F22*Допущения!$D$7 -> 1155846.3 | G23: =G22*Допущения!$D$7 -> 1155846.3 | H23: =H22*Допущения!$D$7 -> 1155846.3 | I23: =I22*Допущения!$D$7 -> 1155846.3 | ... M23: =M22*Допущения!$D$7 -> 1155846.3 | N23: =SUM(B23:M23) -> 13870155
A24: РАСХОД: доплата от механики, ₽ | B24: =B23-B22 -> 330241.8 | C24: =C23-C22 -> 330241.8 | D24: =D23-D22 -> 330241.8 | E24: =E23-E22 -> 330241.8 | F24: =F23-F22 -> 330241.8 | G24: =G23-G22 -> 330241.8 | H24: =H23-H22 -> 330241.8 | I24: =I23-I22 -> 330241.8 | ... M24: =M23-M22 -> 330241.8 | N24: =SUM(B24:M24) -> 3962901.6
A25: ВКЛАД: маржа − бонус с механикой, ₽ | B25: =B21-B23 -> 83737236 | C25: =C21-C23 -> 83737236 | D25: =D21-D23 -> 83737236 | E25: =E21-E23 -> 83737236 | F25: =F21-F23 -> 83737236 | G25: =G21-G23 -> 83737236 | H25: =H21-H23 -> 83737236 | I25: =I21-I23 -> 83737236 | ... M25: =M21-M23 -> 83737236 | N25: =SUM(B25:M25) -> 1.0048468e+09
A26: Доплата, % от грязной маржи | B26: =IFERROR(B24/B21,0) -> 0.0038900908 | C26: =IFERROR(C24/C21,0) -> 0.0038900908 | D26: =IFERROR(D24/D21,0) -> 0.0038900908 | E26: =IFERROR(E24/E21,0) -> 0.0038900908 | F26: =IFERROR(F24/F21,0) -> 0.0038900908 | G26: =IFERROR(G24/G21,0) -> 0.0038900908 | H26: =IFERROR(H24/H21,0) -> 0.0038900908 | I26: =IFERROR(I24/I21,0) -> 0.0038900908 | ... N26: =IFERROR(N24/N21,0) -> 0.0038900908
A28: Тир 🌳 Дерево — ВВ/мес 12 000–35 000 ₽
A29: Показатель | B29: 2026-01 | C29: 2026-02 | D29: 2026-03 | E29: 2026-04 | F29: 2026-05 | G29: 2026-06 | H29: 2026-07 | I29: 2026-08 | J29: 2026-09 | K29: 2026-10 | L29: 2026-11 | M29: 2026-12 | N29: 2026 итого
A30: Юзеров в тире | B30: =Выручка_вход!E6 -> 6938 | C30: =Выручка_вход!E7 -> 6938 | D30: =Выручка_вход!E8 -> 6938 | E30: =Выручка_вход!E9 -> 6938 | F30: =Выручка_вход!E10 -> 6938 | G30: =Выручка_вход!E11 -> 6938 | H30: =Выручка_вход!E12 -> 6938 | I30: =Выручка_вход!E13 -> 6938 | J30: =Выручка_вход!E14 -> 6938 | K30: =Выручка_вход!E15 -> 6938 | L30: =Выручка_вход!E16 -> 6938 | M30: =Выручка_вход!E17 -> 6938 | N30: =AVERAGE(B30:M30) -> 6938
A31: Индекс месяца (эмиссия) | B31: =Допущения!B$34 -> 1 | C31: =Допущения!C$34 -> 1 | D31: =Допущения!D$34 -> 1 | E31: =Допущения!E$34 -> 1 | F31: =Допущения!F$34 -> 1 | G31: =Допущения!G$34 -> 1 | H31: =Допущения!H$34 -> 1 | I31: =Допущения!I$34 -> 1 | ... M31: =Допущения!M$34 -> 1 | N31: =AVERAGE(B31:M31) -> 1
A32: ДОХОД: валовая выручка, ₽ | B32: =B30*Выручка_вход!I6 -> 125133768 | C32: =C30*Выручка_вход!I7 -> 125133768 | D32: =D30*Выручка_вход!I8 -> 125133768 | E32: =E30*Выручка_вход!I9 -> 125133768 | F32: =F30*Выручка_вход!I10 -> 125133768 | G32: =G30*Выручка_вход!I11 -> 125133768 | H32: =H30*Выручка_вход!I12 -> 125133768 | I32: =I30*Выручка_вход!I13 -> 125133768 | J32: =J30*Выручка_вход!I14 -> 125133768 | K32: =K30*Выручка_вход!I15 -> 125133768 | L32: =L30*Выручка_вход!I16 -> 125133768 | M32: =M30*Выручка_вход!I17 -> 125133768 | N32: =SUM(B32:M32) -> 1501605216
A33: ДОХОД: грязная маржа, ₽ | B33: =B32*Допущения!$B$14 -> 37540130 | C33: =C32*Допущения!$B$14 -> 37540130 | D33: =D32*Допущения!$B$14 -> 37540130 | E33: =E32*Допущения!$B$14 -> 37540130 | F33: =F32*Допущения!$B$14 -> 37540130 | G33: =G32*Допущения!$B$14 -> 37540130 | H33: =H32*Допущения!$B$14 -> 37540130 | I33: =I32*Допущения!$B$14 -> 37540130 | ... M33: =M32*Допущения!$B$14 -> 37540130 | N33: =SUM(B33:M33) -> 4.5048156e+08
A34: РАСХОД: эко-бонус базовый, ₽ | B34: =B30*Допущения!$C$27*B31 -> 111351.72 | C34: =C30*Допущения!$C$27*C31 -> 111351.72 | D34: =D30*Допущения!$C$27*D31 -> 111351.72 | E34: =E30*Допущения!$C$27*E31 -> 111351.72 | F34: =F30*Допущения!$C$27*F31 -> 111351.72 | G34: =G30*Допущения!$C$27*G31 -> 111351.72 | H34: =H30*Допущения!$C$27*H31 -> 111351.72 | I34: =I30*Допущения!$C$27*I31 -> 111351.72 | ... M34: =M30*Допущения!$C$27*M31 -> 111351.72 | N34: =SUM(B34:M34) -> 1336220.7
A35: РАСХОД: эко-бонус с механикой, ₽ | B35: =B34*Допущения!$D$8 -> 239406.2 | C35: =C34*Допущения!$D$8 -> 239406.2 | D35: =D34*Допущения!$D$8 -> 239406.2 | E35: =E34*Допущения!$D$8 -> 239406.2 | F35: =F34*Допущения!$D$8 -> 239406.2 | G35: =G34*Допущения!$D$8 -> 239406.2 | H35: =H34*Допущения!$D$8 -> 239406.2 | I35: =I34*Допущения!$D$8 -> 239406.2 | ... M35: =M34*Допущения!$D$8 -> 239406.2 | N35: =SUM(B35:M35) -> 2872874.4
A36: РАСХОД: доплата от механики, ₽ | B36: =B35-B34 -> 128054.48 | C36: =C35-C34 -> 128054.48 | D36: =D35-D34 -> 128054.48 | E36: =E35-E34 -> 128054.48 | F36: =F35-F34 -> 128054.48 | G36: =G35-G34 -> 128054.48 | H36: =H35-H34 -> 128054.48 | I36: =I35-I34 -> 128054.48 | ... M36: =M35-M34 -> 128054.48 | N36: =SUM(B36:M36) -> 1536653.8
A37: ВКЛАД: маржа − бонус с механикой, ₽ | B37: =B33-B35 -> 37300724 | C37: =C33-C35 -> 37300724 | D37: =D33-D35 -> 37300724 | E37: =E33-E35 -> 37300724 | F37: =F33-F35 -> 37300724 | G37: =G33-G35 -> 37300724 | H37: =H33-H35 -> 37300724 | I37: =I33-I35 -> 37300724 | ... M37: =M33-M35 -> 37300724 | N37: =SUM(B37:M37) -> 4.4760869e+08
A38: Доплата, % от грязной маржи | B38: =IFERROR(B36/B33,0) -> 0.0034111357 | C38: =IFERROR(C36/C33,0) -> 0.0034111357 | D38: =IFERROR(D36/D33,0) -> 0.0034111357 | E38: =IFERROR(E36/E33,0) -> 0.0034111357 | F38: =IFERROR(F36/F33,0) -> 0.0034111357 | G38: =IFERROR(G36/G33,0) -> 0.0034111357 | H38: =IFERROR(H36/H33,0) -> 0.0034111357 | I38: =IFERROR(I36/I33,0) -> 0.0034111357 | ... N38: =IFERROR(N36/N33,0) -> 0.0034111357
A40: Тир 🌲 Лес — ВВ/мес ≥ 35 000 ₽
A41: Показатель | B41: 2026-01 | C41: 2026-02 | D41: 2026-03 | E41: 2026-04 | F41: 2026-05 | G41: 2026-06 | H41: 2026-07 | I41: 2026-08 | J41: 2026-09 | K41: 2026-10 | L41: 2026-11 | M41: 2026-12 | N41: 2026 итого
A42: Юзеров в тире | B42: =Выручка_вход!F6 -> 715 | C42: =Выручка_вход!F7 -> 715 | D42: =Выручка_вход!F8 -> 715 | E42: =Выручка_вход!F9 -> 715 | F42: =Выручка_вход!F10 -> 715 | G42: =Выручка_вход!F11 -> 715 | H42: =Выручка_вход!F12 -> 715 | I42: =Выручка_вход!F13 -> 715 | J42: =Выручка_вход!F14 -> 715 | K42: =Выручка_вход!F15 -> 715 | L42: =Выручка_вход!F16 -> 715 | M42: =Выручка_вход!F17 -> 715 | N42: =AVERAGE(B42:M42) -> 715
A43: Индекс месяца (эмиссия) | B43: =Допущения!B$34 -> 1 | C43: =Допущения!C$34 -> 1 | D43: =Допущения!D$34 -> 1 | E43: =Допущения!E$34 -> 1 | F43: =Допущения!F$34 -> 1 | G43: =Допущения!G$34 -> 1 | H43: =Допущения!H$34 -> 1 | I43: =Допущения!I$34 -> 1 | ... M43: =Допущения!M$34 -> 1 | N43: =AVERAGE(B43:M43) -> 1
A44: ДОХОД: валовая выручка, ₽ | B44: =B42*Выручка_вход!J6 -> 38485590 | C44: =C42*Выручка_вход!J7 -> 38485590 | D44: =D42*Выручка_вход!J8 -> 38485590 | E44: =E42*Выручка_вход!J9 -> 38485590 | F44: =F42*Выручка_вход!J10 -> 38485590 | G44: =G42*Выручка_вход!J11 -> 38485590 | H44: =H42*Выручка_вход!J12 -> 38485590 | I44: =I42*Выручка_вход!J13 -> 38485590 | J44: =J42*Выручка_вход!J14 -> 38485590 | K44: =K42*Выручка_вход!J15 -> 38485590 | L44: =L42*Выручка_вход!J16 -> 38485590 | M44: =M42*Выручка_вход!J17 -> 38485590 | N44: =SUM(B44:M44) -> 461827080
...

Sheet Миграция
A1: Unit-экономика перехода между тирами
A2: Сколько приносит один пользователь, поднявший валовую выручку до следующего тира. Всё — на одного мигранта в месяц.
A4: Шаг перехода | B4: Ед. | C4: ① Старт → Росток | D4: ② Росток → Дерево | E4: ③ Дерево → Лес
A5: ВВ на юзера: исходный тир | B5: ₽/юзер/мес | C5: ='Unit-экономика'!C$7 -> 1075 | D5: ='Unit-экономика'!D$7 -> 5501 | E5: ='Unit-экономика'!E$7 -> 18036
A6: ВВ на юзера: целевой тир | B6: ₽/юзер/мес | C6: ='Unit-экономика'!D$7 -> 5501 | D6: ='Unit-экономика'!E$7 -> 18036 | E6: ='Unit-экономика'!F$7 -> 53826
A7: Δ ВВ (прирост выручки) | B7: ₽/юзер/мес | C7: =C6-C5 -> 4426 | D7: =D6-D5 -> 12535 | E7: =E6-E5 -> 35790
A8: Δ грязная маржа (ДОХОД) | B8: ₽/юзер/мес | C8: =C7*Допущения!$B$14 -> 1327.8 | D8: =D7*Допущения!$B$14 -> 3760.5 | E8: =E7*Допущения!$B$14 -> 10737
A9: Множитель: исходный тир | B9: × | C9: =Допущения!$D$6 -> 1 | D9: =Допущения!$D$7 -> 1.4 | E9: =Допущения!$D$8 -> 2.15
A10: Множитель: целевой тир | B10: × | C10: =Допущения!$D$7 -> 1.4 | D10: =Допущения!$D$8 -> 2.15 | E10: =Допущения!$D$9 -> 2.85
A11: Δ эко-бонус (РАСХОД) | B11: ₽/юзер/мес | C11: =Допущения!$C$25*(C10-C9) -> 6.4198168 | D11: =Допущения!$C$26*(D10-D9) -> 12.037157 | E11: =Допущения!$C$27*(E10-E9) -> 11.234679
A12: ЧИСТЫЙ ЭФФЕКТ на мигранта | B12: ₽/юзер/мес | C12: =C8-C11 -> 1321.3802 | D12: =D8-D11 -> 3748.4628 | E12: =E8-E11 -> 10725.765
A13: Δ бонус, % от Δ маржи | B13: % | C13: =IFERROR(C11/C8,0) -> 0.0048349276 | D13: =IFERROR(D11/D8,0) -> 0.0032009458 | E13: =IFERROR(E11/E8,0) -> 0.0010463518
A14: Пул-источник: юзеров в исходном тире | B14: чел | C14: ='Unit-экономика'!C$6 -> 189856 | D14: ='Unit-экономика'!D$6 -> 51441 | E14: ='Unit-экономика'!E$6 -> 6938
A17: Почему переход почти всегда выгоден
A18: Δ маржа считается в рублях выручки (тысячи ₽), а Δ бонус — в рублях эко-начисления (единицы ₽), потому что база эко-бонуса ≈ 16 ₽/юзер/мес. Отсюда «Δ бонус, % от Δ маржи» — доли процента. Риск механики не в стоимости перехода, а в «слепой» доплате тем, кто уже в высоком тире и поведение не менял (лист «Тир_Период»).

Sheet Сценарии
A1: Сценарии конверсии и порог безубыточности
A2: Конверсия — доля пула исходного тира, переходящая в целевой тир за год.
A4: Показатель | B4: Ед. | C4: Пессимистичный | D4: Базовый | E4: Оптимистичный
A5: Конверсия шага ① | B5: % пула/год | C5: 0.05 | D5: 0.1 | E5: 0.2
A6: Конверсия шага ② | B6: % пула/год | C6: 0.05 | D6: 0.1 | E6: 0.2
A7: Конверсия шага ③ | B7: % пула/год | C7: 0.03 | D7: 0.05 | E7: 0.1
A9: Мигрантов за год | B9: чел | C9: =Миграция!$C$14*C5+Миграция!$D$14*C6+Миграция!$E$14*C7 -> 12272.99 | D9: =Миграция!$C$14*D5+Миграция!$D$14*D6+Миграция!$E$14*D7 -> 24476.6 | E9: =Миграция!$C$14*E5+Миграция!$D$14*E6+Миграция!$E$14*E7 -> 48953.2
A10: Месяцев работы мигранта в первый год | B10: мес | C10: 6 | D10: 6 | E10: 6
A11: ДОХОД: прирост грязной маржи за год | B11: ₽/год | C11: =C10*(Миграция!$C$14*C5*Миграция!$C$8+Миграция!$D$14*C6*Миграция!$D$8+Миграция!$E$14*C7*Миграция!$E$8) -> 1.470692e+08 | D11: =D10*(Миграция!$C$14*D5*Миграция!$C$8+Миграция!$D$14*D6*Миграция!$D$8+Миграция!$E$14*D7*Миграция!$E$8) -> 2.896688e+08 | E11: =E10*(Миграция!$C$14*E5*Миграция!$C$8+Миграция!$D$14*E6*Миграция!$D$8+Миграция!$E$14*E7*Миграция!$E$8) -> 5.793376e+08
A12: РАСХОД: бонусы мигрантов за год | B12: ₽/год | C12: =C10*(Миграция!$C$14*C5*Миграция!$C$11+Миграция!$D$14*C6*Миграция!$D$11+Миграция!$E$14*C7*Миграция!$E$11) -> 565443.55 | D12: =D10*(Миграция!$C$14*D5*Миграция!$C$11+Миграция!$D$14*D6*Миграция!$D$11+Миграция!$E$14*D7*Миграция!$E$11) -> 1126210.3 | E12: =E10*(Миграция!$C$14*E5*Миграция!$C$11+Миграция!$D$14*E6*Миграция!$D$11+Миграция!$E$14*E7*Миграция!$E$11) -> 2252420.7
A13: РАСХОД: слепая доплата за год | B13: ₽/год | C13: =Тир_Период!$N$59 -> 5754309.7 | D13: =Тир_Период!$N$59 -> 5754309.7 | E13: =Тир_Период!$N$59 -> 5754309.7
A14: ЧИСТЫЙ ЭФФЕКТ за год | B14: ₽/год | C14: =C11-C12-C13 -> 1.4074945e+08 | D14: =D11-D12-D13 -> 2.8278828e+08 | E14: =E11-E12-E13 -> 5.7133087e+08
A15: Все бонусные затраты, % от прироста маржи | B15: % | C15: =IFERROR((C12+C13)/C11,0) -> 0.042971291 | D15: =IFERROR((D12+D13)/D11,0) -> 0.023753059 | E15: =IFERROR((E12+E13)/E11,0) -> 0.013820492
A18: Порог безубыточности
A19: Единая конверсия по всем трём шагам, при которой чистый эффект = 0 | B19: % пула/год | C19: =IFERROR(Тир_Период!$N$59/($C$10*(Миграция!$C$14*(Миграция!$C$8-Миграция!$C$11)+Миграция!$D$14*(Миграция!$D$8-Миграция!$D$11)+Миграция!$E$14*(Миграция!$E$8-Миграция!$E$11))),0) -> 0.0018510508
A21: Запас до порога: базовый сценарий / порог | B21: × | C21: =IFERROR(AVERAGE(D5:D7)/$C$19,0) -> 45.019474
A23: Итог по когорте за 2026 год (из листа «Тир_Период»)
A24: ДОХОД: валовая выручка | B24: ₽/год | C24: =Тир_Период!$N$55 -> 7808297988
A25: ДОХОД: грязная маржа | B25: ₽/год | C25: =Тир_Период!$N$56 -> 2.3424894e+09
A26: РАСХОД: эко-бонус базовый (как сейчас) | B26: ₽/год | C26: =Тир_Период!$N$57 -> 47946402
A27: РАСХОД: эко-бонус с механикой | B27: ₽/год | C27: =Тир_Период!$N$58 -> 53700711
A28: РАСХОД: доплата от механики (слепая) | B28: ₽/год | C28: =Тир_Период!$N$59 -> 5754309.7
A29: ВКЛАД до учёта миграции | B29: ₽/год | C29: =Тир_Период!$N$60 -> 2.2887887e+09
A31: Порог безубыточности — не прогноз, а свойство конструкции: он показывает, какая доля пула должна подняться в следующий тир, чтобы окупить слепую доплату. Реальную конверсию даст только A/B с holdout.
